Workbook

Sheet Лист 1
A1: Прайс-лист на запасные части
A2: Наименование организации | C2: ООО "БТЛ-Сервис"
A3: ИНН | C3: 7536164300
A4: Юр. Адрес | C4: 117342, город Москва, вн.тер.г. муниципальный округ Коньково, улица Бутлерова, дом 17Б, помещение 60Б/11/2
A5: Адрес эл. почты контактного лица | C5: A.Skachkov@btlogistic.ru
A6: ____________________________________ (подпись, М.П.) ____________________________________ (ФИО подписавшего, должность)
A8: № п/п | B8: Код ОКП | C8: Наименование запасной части | D8: Каталожный номер/артикул | E8: Рекомендованная розничная цена в USD/РУБ, без НДС за шт., действующая до изменения на заводе-изготовителе (с учётом доставки до Красноярска (+5%))
A9: 1 | B9: =D9 -> BELAZ G-Profi Trans 80W-90 | C9: Масло трансмиссионное BELAZ G-Profi Trans 80W-90, л | D9: BELAZ G-Profi Trans 80W-90 | E9: 379.61
A10: 2 | B10: =D10 -> BELAZ G-Profi Trans Plus 680 | C10: Масло трансмиссионное BELAZ G-Profi Trans Plus 680, л | D10: BELAZ G-Profi Trans Plus 680 | E10: 1070.71
A11: 3 | B11: =D11 -> Samson EU-Standard G13/G12++ | C11: Антифриз Samson EU-Standard G13/G12++ фиолетовый, кг | D11: Samson EU-Standard G13/G12++ | E11: 2554.256
A12: 4 | B12: =D12 -> L140 | C12: ЩЕТКА ЭЛЕКТРОГРАФИТОВАЯ ЭГ-74 25*32*40 L140 | D12: L140 | E12: 951.8544
A13: 5 | B13: =D13 -> EKO-01.24 | C13: ФИЛЬТР ВОЗДУШНЫЙ ЕКО-01.24 (040-1109080 / НСФ-01-09 / AG334) | D13: EKO-01.24 | E13: 557.28809
A14: 6 | B14: =D14 -> 3563825 | C14: Жидкость охлаждающая низкозамерзающая ЛУКОЙЛ АНТИФРИЗ G12++ , л | D14: 3563825 | E14: 208.98303
A15: 7 | B15: =D15 -> 1720236 | C15: Смазка Синтофлекс 2-100 0,4 кг | D15: 1720236 | E15: 1628.8
A16: 8 | B16: =D16 -> ДИФА-4238 | C16: Фильтр воздушный ДИФА-4238 | D16: ДИФА-4238 | E16: 1272.8
A17: 9 | B17: =D17 -> ЕЕ 102227 (432 410 222 7) | C17: Фильтр осушителя | D17: ЕЕ 102227 (432 410 222 7) | E17: 1133.9
A18: 10 | B18: =D18 -> ЕЕ100300 (В4305МК) | C18: Фильтр воздушный внешний | D18: ЕЕ100300 (В4305МК) | E18: 6155.7
A19: 11 | B19: =D19 -> ЕЕ100301 (В4305MK-01) | C19: Фильтр воздушный предохранительный | D19: ЕЕ100301 (В4305MK-01) | E19: 2446.3
A20: 12 | B20: =D20 -> EE500600/М5409МК | C20: Фильтр масляного бака | D20: EE500600/М5409МК | E20: 7893.1
A21: 13 | B21: =D21 -> 120-130-58-2-2 | C21: Кольцо обогревателя топлива | D21: 120-130-58-2-2 | E21: 100.5
A22: 14 | B22: =D22 -> EE502300 (М5402МК) | C22: Фильтр масляный р.у. | D22: EE502300 (М5402МК) | E22: 1815.6
A23: 15 | B23: =D23 -> ЕЕ 148200 (В4701МК) | C23: Фильтр воздушный кабины | D23: ЕЕ 148200 (В4701МК) | E23: 1569.1
A24: 16 | B24: =D24 -> EE100310 (4347МК) | C24: Фильтр сапуна маслобака и РМК | D24: EE100310 (4347МК) | E24: 363.8
A25: 17 | B25: =D25 -> ЕЕ 300100 (240-1017040) | C25: ФИЛЬТР МАСЛЯНЫЙ ЕЕ 300100 (240-1017040) | D25: ЕЕ 300100 (240-1017040) | E25: 323.78
A26: 18 | B26: =D26 -> ЕЕ 300500 (М5203) | C26: ФИЛЬТР МАСЛЯНЫЙ ЕЕ 300500 (М5203) | D26: ЕЕ 300500 (М5203) | E26: 1124.66
A27: 19 | B27: =D27 -> ЕЕ 790420 (PL420) | C27: ФИЛЬТР ТОПЛИВНЫЙ ЕЕ 790420 (PL420) | D27: ЕЕ 790420 (PL420) | E27: 1972.82
... A64: 56 | B64: =D64 -> 200333-П29 | C64: БОЛТ 200333-П29 (креп/впуск коллектора) М10*1,5*120 | D64: 200333-П29 | E64: 63.625518
A65: 57 | B65: =D65 -> 201454 | C65: БОЛТ M8-6gx16 201454 | D65: 201454 | E65: 11.57098
A66: 58 | B66: =D66 -> 240-1005537 (310001-П2) | C66: Болт крепления полумуфты отбора мощности ЯМЗ-240 240-1005537 (310001-П2) | D66: 240-1005537 (310001-П2) | E66: 480.06182
A67: 59 | B67: =D67 -> 236-1004063-БЗ | C67: БОЛТ КРЫШКИ ШАТУНА ДЛИННЫЙ (ЯМЗ) 236-1004063-БЗ | D67: 236-1004063-БЗ | E67: 595.73196
A68: 60 | B68: =D68 -> 236-1004062-БЗ | C68: БОЛТ КРЫШКИ ШАТУНА КОРОТКИЙ (ЯМЗ) 236-1004062-БЗ | D68: 236-1004062-БЗ | E68: 653.57694
A69: 61 | B69: =D69 -> 200274-П29 | C69: БОЛТ М 8*1,25*75 (ЯМЗ) 200274-П29 | D69: 200274-П29 | E69: 17.351513
A70: 62 | B70: =D70 -> 310239-П29 | C70: БОЛТ М10х1-6gх40 310239-П29 | D70: 310239-П29 | E70: 109.88961
A71: 63 | B71: =D71 -> M6*25 | C71: БОЛТ М6*25 черн. | D71: M6*25 | E71: 11.57098
A72: 64 | B72: =D72 -> 240-3708720 | C72: БОЛТ СТЯЖНОЙ 240-3708720 | D72: 240-3708720 | E72: 150.38308
A73: 65 | B73: =D73 -> 240-1104336-Б | C73: Втулка уплотнит. трубки подвода масла к ТКР ЯМЗ-236, 238, 240 240-1104336-Б | D73: 240-1104336-Б | E73: 17.351513
A74: 66 | B74: =D74 -> 240-1007247 | C74: ВТУЛКА ОСИ ТОЛКАТЕЛЕЙ 240-1007247 (крайняя) | D74: 240-1007247 | E74: 433.78781
A75: 67 | B75: =D75 -> 236-1006037-AP | C75: Втулка 53х68х30 р/в ЯМЗ рем. 236-1006037-АР | D75: 236-1006037-AP | E75: 1978.0724
A76: 68 | B76: =D76 -> 236-1007186 | C76: ВТУЛКА ТОЛКАТЕЛЯ 236-1007186 | D76: 236-1007186 | E76: 104.10907
A77: 69 | B77: =D77 -> 311412-П29 | C77: Гайка М27Х2 ШС р/в ЯМЗ (С58) 311412-П29 | D77: 311412-П29 | E77: 289.19518
...
